Workbook

Sheet Guia
A1: Modelo de evaluación de madurez de la información para estimación de proyectos
A3: Propósito | B3: Evaluar, antes de estimar, qué tanto se conoce el alcance del proyecto en cada dimensión de estimación y qué tan madura es esa información. El resultado indica la confianza con la que se puede estimar, la técnica recomendada y las brechas a cerrar.
A4: Qué NO mide | B4: No estima esfuerzo ni costo. No evalúa riesgo e incertidumbre (dimensión 12 del catálogo, fuera de alcance).
A5: Hojas del libro | B5: Guia · Dimensiones (11 dimensiones y escalas) · Rubricas (109 criterios con descriptores 0–3) · Parametros (pesos, niveles, umbrales) · Ficha (plantilla en blanco) · Ejemplo (ficha diligenciada) · Resultados (tablero de la ficha seleccionada) · Glosario.
A6: Paso 1 · Datos generales | B6: En la hoja Ficha, completar proyecto, cliente, evaluadores, fecha, momento de estimación y fuentes revisadas.
A7: Paso 2 · Caracterización (Parte A) | B7: Registrar los valores de clasificación del catálogo: composición del tipo de desarrollo, arquetipo, N° de procesos funcionales, factores de complejidad, interfaces, % de reuso, entorno, contexto, sector y comparables. La hoja calcula la clase de tamaño, el nivel de complejidad, I0–I3, R1–R4, M1–M4 y E1–E4.
A8: Paso 3 · Evaluación (Parte B) | B8: Calificar cada criterio de 0 a 3 con la rúbrica de la hoja Rubricas, y registrar la evidencia. Usar N/A solo cuando el criterio lo admite.
A9: Paso 4 · Revisar hallazgos | B9: La columna «Hallazgo o comentario sugerido» explica la brecha cuando el puntaje es 0–1 y pide validar cuando es 2.
A10: Paso 5 · Revisar validaciones | B10: El bloque de validaciones cruza la caracterización con los criterios y marca inconsistencias (⚠ Revisar).
A11: Paso 6 · Resultados | B11: En la hoja Resultados seleccionar la ficha (Ejemplo o Ficha) para ver madurez por dimensión, nivel general, top 10 brechas y validaciones.
A12: Cálculo · criterio | B12: Obtenido = puntaje × peso interno (1–3). Máximo = 3 × peso interno (0 si es N/A).
A13: Cálculo · dimensión | B13: Madurez de la dimensión = Σ obtenido / Σ máximo (0–100%). Criterio núcleo en blanco cuenta como 0. Dimensión complementaria sin ningún puntaje se excluye.
A14: Cálculo · general | B14: Madurez general = Σ (peso dimensión × madurez) / Σ peso de dimensiones incluidas. Núcleo = 70% del peso; cada núcleo pesa más que cualquier complementaria.
... A19: Reutilizar la ficha | B19: Para un nuevo proyecto, copiar la hoja Ficha (clic derecho › Mover o copiar) o limpiar las celdas amarillas. Para ver sus resultados en la hoja Resultados, el nombre debe ser «Ficha» o «Ejemplo» (o agregarlo a la lista de C3).

Sheet Dimensiones
A1: Dimensiones de estimación, subdimensiones y escalas de caracterización
A2: Se evalúan 11 dimensiones. La dimensión 12 (Riesgo e incertidumbre) queda fuera de este modelo. Las 5 dimensiones núcleo son obligatorias y concentran el mayor peso.
A3: Código | B3: Dimensión | C3: Tipo | D3: Peso | E3: Qué busca caracterizar | F3: Cómo determinarla | G3: Escala de caracterización (catálogo) | H3: Subdimensiones | I3: N° criterios | J3: Suma pesos internos | K3: Referencia
A4: D1 | B4: Tipo de desarrollo | C4: Núcleo | D4: =Parametros!D5 -> 0.12 | E4: Qué se está haciendo sobre el activo de software. | F4: Identificar qué porcentaje del alcance corresponde a crear, modificar, reemplazar o corregir software existente. | G4: Nuevo desarrollo / Enhancement-evolutivo / Modernización-redevelopment / Mantenimiento (componente predominante > 50%). | H4: Composición del cambio · Línea base del activo · Frontera y componentes · Impacto y regresión | I4: =COUNTIF(Rubricas!$B$4:$B$112,A4) -> 12 | J4: =SUMIF(Rubricas!$B$4:$B$112,A4,Rubricas!$M$4:$M$112) -> 27 | K4: ISBSG (Development Type) + GAO (software nuevo, modificado, reutilizado)
A5: D2 | B5: Tipo de solución / arquetipo | C5: Núcleo | D5: =Parametros!D6 -> 0.11 | E5: Naturaleza predominante de lo que se construye. | F5: Determinar el objeto tecnológico predominante del esfuerzo con la pregunta dominante del catálogo. | G5: Aplicaciones · Integración · Datos/IA · Plataforma · Seguridad · Modernización (principal + secundarios). | H5: Objeto predominante · Distribución del esfuerzo · Drivers de esfuerzo · Validación de la clasificación | I5: =COUNTIF(Rubricas!$B$4:$B$112,A5) -> 12 | J5: =SUMIF(Rubricas!$B$4:$B$112,A5,Rubricas!$M$4:$M$112) -> 23 | K5: ISBSG (Application Group/Type) + adaptación organizacional
A6: D3 | B6: Tamaño funcional | C6: Núcleo | D6: =Parametros!D7 -> 0.18 | E6: Cuánto producto debe construirse o modificarse. | F6: Medir la cantidad de funcionalidad mediante procesos funcionales y movimientos de datos (o unidad interna calibrada). | G6: XS (1–5) · S (6–15) · M (16–30) · L (31–60) · XL (>60) procesos funcionales; tamaño en puntos de función. | H6: Estrategia de medición · Usuarios funcionales y frontera · Procesos funcionales · Datos · Movimientos de datos · Requisitos no funcionales · Consolidación | I6: =COUNTIF(Rubricas!$B$4:$B$112,A6) -> 14 | J6: =SUMIF(Rubricas!$B$4:$B$112,A6,Rubricas!$M$4:$M$112) -> 31 | K6: ISBSG + GAO + medición funcional ISO/IEC 19761
A7: D4 | B7: Complejidad | C7: Núcleo | D7: =Parametros!D8 -> 0.15 | E7: Qué tan difícil es implementar ese tamaño. | F7: Calificar 5 factores de 0 a 2 (reglas, arquitectura, seguridad, procesamiento, dependencias). | G7: 0–2 Baja · 3–5 Media · 6–8 Alta · 9–10 Muy alta. | H7: Reglas de negocio · Procesamiento · Arquitectura · Seguridad · Calidad y operación · Cumplimiento · Dependencias · Consolidación | I7: =COUNTIF(Rubricas!$B$4:$B$112,A7) -> 12 | J7: =SUMIF(Rubricas!$B$4:$B$112,A7,Rubricas!$M$4:$M$112) -> 26 | K7: GAO (complejidad funcional y técnica)
A8: D5 | B8: Integración / interdependencia | C8: Núcleo | D8: =Parametros!D9 -> 0.14 | E8: Cuánto depende la solución de otros sistemas. | F8: Contar interfaces y evaluar su dificultad (cantidad + dificultad). | G8: I0 sin interfaces · I1 1–2 simples · I2 3–5 o alguna compleja · I3 >5, sistemas críticos, protocolos no conocidos o múltiples terceros. | H8: Inventario de interfaces · Contratos y protocolos · Transformación de datos · Comportamiento y errores · Seguridad de integración · Terceros y ambientes · Consolidación | I8: =COUNTIF(Rubricas!$B$4:$B$112,A8) -> 13 | J8: =SUMIF(Rubricas!$B$4:$B$112,A8,Rubricas!$M$4:$M$112) -> 28 | K8: GAO (interfaces e interacciones)
A9: D6 | B9: Novedad y reutilización | C9: Complementaria | D9: =Parametros!D10 -> 0.05 | E9: Cuánto puede aprovecharse de activos existentes. | F9: Estimar qué porcentaje del alcance puede resolverse con conocimiento, código, componentes o patrones existentes. | G9: R1 >70% · R2 40–70% · R3 10–40% · R4 <10% reutilizable. | H9: Inventario de activos · Clasificación del reuso · Calidad del activo · Consolidación | I9: =COUNTIF(Rubricas!$B$4:$B$112,A9) -> 7 | J9: =SUMIF(Rubricas!$B$4:$B$112,A9,Rubricas!$M$4:$M$112) -> 13 | K9: GAO (nuevo, adaptado, reutilizado, autogenerado)
A10: D7 | B10: Entorno tecnológico | C10: Complementaria | D10: =Parametros!D11 -> 0.05 | E10: Contexto técnico en que será implementado. | F10: Identificar tecnología y grado de familiaridad del equipo. | G10: T1 Conocido · T2 Parcialmente conocido · T3 Nuevo · T4 Experimental. | H10: Stack · Plataforma y datos · Familiaridad · Herramientas y ambientes · Restricciones | I10: =COUNTIF(Rubricas!$B$4:$B$112,A10) -> 7 | J10: =SUMIF(Rubricas!$B$4:$B$112,A10,Rubricas!$M$4:$M$112) -> 15 | K10: ISBSG + GAO
A11: D8 | B11: Madurez del alcance | C11: Complementaria | D11: =Parametros!D12 -> 0.07 | E11: Cuánto se conoce realmente de lo solicitado. | F11: Checklist de 8 elementos del catálogo (objetivo, roles, funcionalidades, reglas, integraciones, datos, RNF, criterios de aceptación). | G11: M1 Idea (0–2) · M2 Preliminar (3–4) · M3 Definido (5–6) · M4 Validado (7–8) elementos con puntaje ≥ 2. | H11: Definición del problema · Requisitos funcionales · Datos e integraciones · Requisitos no funcionales · Criterios de aceptación · Límites y validación | I11: =COUNTIF(Rubricas!$B$4:$B$112,A11) -> 11 | J11: =SUMIF(Rubricas!$B$4:$B$112,A11,Rubricas!$M$4:$M$112) -> 23 | K11: GAO + propuesta
A12: D9 | B12: Contexto de ejecución | C12: Complementaria | D12: =Parametros!D13 -> 0.05 | E12: Condiciones bajo las cuales se desarrollará. | F12: Evaluar condiciones del equipo y forma de ejecución (8 variables del catálogo). | G12: Estable · Parcialmente conocido · Incierto. | H12: Equipo · Forma de trabajo · Dependencias externas | I12: =COUNTIF(Rubricas!$B$4:$B$112,A12) -> 8 | J12: =SUMIF(Rubricas!$B$4:$B$112,A12,Rubricas!$M$4:$M$112) -> 16 | K12: GAO + ISBSG
A13: D10 | B13: Sector / contexto de negocio | C13: Complementaria | D13: =Parametros!D14 -> 0.03 | E13: Condiciones externas que afectan el proyecto. | F13: Clasificar dominio y restricciones externas. | G13: Gobierno · Financiero · Salud · Comercio · Telecomunicaciones · Otros. | H13: Dominio · Regulación · Contratación y gobierno del proyecto | I13: =COUNTIF(Rubricas!$B$4:$B$112,A13) -> 6 | J13: =SUMIF(Rubricas!$B$4:$B$112,A13,Rubricas!$M$4:$M$112) -> 11 | K13: ISBSG
A14: D11 | B14: Evidencia histórica disponible | C14: Complementaria | D14: =Parametros!D15 -> 0.05 | E14: Qué tan comparable es el histórico utilizado. | F14: Evaluar cantidad, similitud y calidad de los proyectos comparables (p. ej. Jira). | G14: E1 0–1 · E2 2–3 · E3 4–7 · E4 ≥8 comparables. | H14: Cantidad y similitud · Calidad del dato · Explotación del histórico | I14: =COUNTIF(Rubricas!$B$4:$B$112,A14) -> 7 | J14: =SUMIF(Rubricas!$B$4:$B$112,A14,Rubricas!$M$4:$M$112) -> 16 | K14: ISBSG + GAO
C15: Total | D15: =SUM(D4:D14) -> 1 | I15: =SUM(I4:I14) -> 109

Sheet Rubricas
A1: Matriz de rúbricas y subdimensiones
A2: Cada criterio se califica de 0 a 3 según los descriptores. El peso interno (1–3) indica la importancia del criterio dentro de su dimensión. El hallazgo sugerido se muestra en la ficha cuando el puntaje es 0 o 1.
A3: ID | B3: Código | C3: Dimensión | D3: Tipo | E3: Subdimensión | F3: Criterio | G3: Pregunta de evaluación | H3: Evidencia esperada | I3: 0 – Sin información | J3: 1 – Parcial / supuesto | K3: 2 – Definido con vacíos | L3: 3 – Completo y validado | M3: Peso interno (1–3) | N3: ¿Admite N/A? | O3: Hallazgo sugerido (puntaje 0–1) | P3: Origen
A4: D1.01 | B4: D1 | C4: Tipo de desarrollo | D4: Núcleo | E4: Composición del cambio | F4: Composición del alcance cuantificada | G4: ¿Se conoce qué porcentaje del alcance corresponde a crear, modificar, reemplazar/transformar o corregir software? | H4: Tabla de composición por tipo de cambio que suma 100%. | I4: No se conoce la naturaleza del cambio. | J4: Se describe cualitativamente (p. ej. «es un desarrollo nuevo») sin cuantificar. | K4: Porcentajes estimados por juicio, sin detalle por funcionalidad. | L4: Porcentajes derivados del inventario de funcionalidades clasificadas por tipo de cambio. | M4: 3 | N4: No | O4: No está cuantificada la proporción nuevo / modificado / reemplazado / correctivo. Clasificar cada funcionalidad del inventario por tipo de cambio y totalizar. | P4: Catálogo
A5: D1.02 | B5: D1 | C5: Tipo de desarrollo | D5: Núcleo | E5: Composición del cambio | F5: Tipo de desarrollo asignado y justificado | G5: ¿El tipo de desarrollo (Nuevo, Enhancement/evolutivo, Modernización/redevelopment, Mantenimiento) está asignado según el componente predominante? | H5: Clasificación registrada con justificación trazable a la composición. | I5: No asignado. | J5: Asignado por el nombre del proyecto o por percepción. | K5: Asignado según la composición, sin justificación documentada. | L5: Asignado por el componente predominante (>50%) y justificado; componentes secundarios registrados. | M5: 3 | N5: No | O5: El tipo de desarrollo no está asignado o no se justifica con la composición del alcance. Asignarlo según el tipo de cambio que concentra la mayor proporción. | P5: Catálogo
A6: D1.03 | B6: D1 | C6: Tipo de desarrollo | D6: Núcleo | E6: Línea base del activo | F6: Línea base funcional del sistema existente | G6: ¿Existe inventario de las funcionalidades actuales del sistema que se modifica, reemplaza o mantiene? | H6: Inventario funcional, manual de usuario o medición previa del sistema. | I6: No hay información del sistema actual. | J6: Solo conocimiento tácito de personas clave. | K6: Documentación parcial o desactualizada. | L6: Inventario funcional actualizado (idealmente con tamaño medido). | M6: 2 | N6: Sí | O6: No hay línea base funcional del activo existente; sin ella no puede medirse el tamaño del cambio ni el alcance de regresión. Levantar el inventario de funcionalidades actuales. | P6: Medición funcional
A7: D1.04 | B7: D1 | C7: Tipo de desarrollo | D7: Núcleo | E7: Composición del cambio | F7: Funcionalidades nuevas identificadas | G7: ¿Se listan las funcionalidades que se agregan, desagregadas al nivel de proceso funcional? | H7: Listado de funcionalidades nuevas con identificador único. | I7: No se han identificado. | J7: Descritas como módulos o épicas. | K7: Listadas con granularidad heterogénea. | L7: Listadas a nivel de proceso funcional (responde a un evento y termina al completar su respuesta) con ID. | M7: 3 | N7: Sí | O7: Las funcionalidades nuevas no están desagregadas a nivel de proceso funcional. Descomponer módulos/épicas en acciones completas iniciadas por un evento. | P7: Medición funcional
A8: D1.05 | B8: D1 | C8: Tipo de desarrollo | D8: Núcleo | E8: Composición del cambio | F8: Funcionalidades modificadas y naturaleza del cambio | G8: Para cada funcionalidad existente que cambia, ¿se identifica qué datos que entran, salen, se consultan o se almacenan se agregan, modifican o eliminan? | H8: Lista de funcionalidades impactadas con el detalle de los movimientos de datos afectados. | I8: No identificadas. | J8: Se sabe que hay cambios en ciertos módulos, sin listar funcionalidades. | K8: Funcionalidades impactadas listadas, sin detalle del cambio. | L8: Funcionalidades y movimientos de datos agregados / modificados / eliminados identificados. | M8: 3 | N8: Sí | O8: No se detalla qué cambia en las funcionalidades existentes. En evolutivos el tamaño es la suma de movimientos de datos agregados, modificados y eliminados; identificarlos. | P8: Medición funcional
A9: D1.06 | B9: D1 | C9: Tipo de desarrollo | D9: Núcleo | E9: Composición del cambio | F9: Funcionalidades retiradas | G9: ¿Se identifican funcionalidades, interfaces o datos que se eliminan o dan de baja (o se declara explícitamente que no existen)? | H9: Listado de retiros o declaración explícita de ausencia. | I9: No se ha analizado. | J9: Se mencionan retiros sin detalle. | K9: Retiros listados sin análisis de impacto (o ausencia no confirmada). | L9: Retiros listados con impacto en datos, usuarios e interfaces, o ausencia confirmada. | M9: 1 | N9: Sí | O9: No se ha analizado si hay funcionalidad a retirar; los retiros también consumen esfuerzo (movimientos eliminados, datos, pruebas). Confirmarlo explícitamente. | P9: Medición funcional
A10: D1.07 | B10: D1 | C10: Tipo de desarrollo | D10: Núcleo | E10: Frontera y componentes | F10: Frontera del software definida | G10: ¿Está claro qué software se construye o modifica (dentro del alcance) y qué sistemas, usuarios o componentes quedan fuera? | H10: Diagrama de contexto con piezas de software en alcance y actores externos. | I10: No definida. | J10: Implícita o ambigua. | K10: Diagrama de contexto sin validar o con ambigüedades menores. | L10: Frontera validada con piezas en alcance y usuarios externos explícitos. | M10: 3 | N10: No | O10: La frontera del software no es explícita; hay riesgo de contar de más o de menos. Elaborar diagrama de contexto con piezas en alcance y sistemas externos. | P10: Medición funcional
A11: D1.08 | B11: D1 | C11: Tipo de desarrollo | D11: Núcleo | E11: Frontera y componentes | F11: Capas y componentes afectados | G11: ¿Se identifican las capas (presentación, negocio, servicios, datos) y los componentes que se crean o modifican? | H11: Vista de arquitectura con componentes marcados como nuevos o modificados. | I11: No identificados. | J11: Se mencionan tecnologías sin ubicar componentes. | K11: Componentes identificados sin clasificar nuevo/modificado. | L11: Componentes por capa identificados y clasificados. | M11: 2 | N11: No | O11: No se identifican componentes/capas afectados; cada componente con frontera propia puede requerir medición y pruebas independientes. | P11: Medición funcional
A12: D1.09 | B12: D1 | C12: Tipo de desarrollo | D12: Núcleo | E12: Línea base del activo | F12: Documentación técnica y código del activo | G12: ¿Están disponibles y actualizados el código fuente, la documentación técnica y los ambientes del sistema existente? | H12: Acceso confirmado a repositorio, arquitectura y modelo de datos. | I12: No disponible. | J12: Disponible parcialmente o sin acceso confirmado. | K12: Disponible con vacíos conocidos. | L12: Disponible, actualizado y con acceso confirmado. | M12: 2 | N12: Sí | O12: No se confirma acceso ni estado del código/documentación del activo existente; aumenta el esfuerzo de análisis. Solicitar acceso y evaluar su estado. | P12: Buenas prácticas
A13: D1.10 | B13: D1 | C13: Tipo de desarrollo | D13: Núcleo | E13: Impacto y regresión | F13: Alcance de regresión | G13: ¿Se conocen las funcionalidades existentes que deben volver a probarse por efecto de los cambios? | H13: Matriz de impacto o suite de regresión identificada. | I13: No se ha considerado. | J13: Se reconoce la necesidad sin identificar funcionalidades. | K13: Funcionalidades a regresionar identificadas, sin estrategia. | L13: Alcance y estrategia de regresión definidos (manual/automatizada, suites existentes). | M13: 2 | N13: Sí | O13: No está definido el alcance de regresión; en evolutivos y modernizaciones es un driver de esfuerzo relevante. | P13: Buenas prácticas
A14: D1.11 | B14: D1 | C14: Tipo de desarrollo | D14: Núcleo | E14: Impacto y regresión | F14: Equivalencia funcional en modernización | G14: Cuando se transforma un activo, ¿se define qué comportamiento debe preservarse y cómo se verificará la equivalencia? | H14: Criterios de equivalencia y casos de referencia. | I14: No definido. | J14: Se asume «igual al actual» sin detalle. | K14: Funcionalidades a preservar listadas, sin criterio de verificación. | L14: Funcionalidades a preservar, cambios aceptados y método de verificación definidos. | M14: 2 | N14: Sí | O14: En la modernización no se define qué debe preservarse ni cómo verificar la equivalencia funcional. | P14: Catálogo
A15: D1.12 | B15: D1 | C15: Tipo de desarrollo | D15: Núcleo | E15: Composición del cambio | F15: Separación correctivo vs. evolutivo | G15: ¿Se distinguen las correcciones de defectos de los cambios y nuevas funcionalidades? | H15: Backlog clasificado (defecto / cambio / nueva funcionalidad). | I15: Mezclado sin clasificar. | J15: Separación parcial. | K15: Separado sin criterio formal. | L15: Clasificado con criterio acordado. | M15: 1 | N15: No | O15: Correcciones y nuevos requerimientos no están separados; distorsiona el tipo de desarrollo y la comparación con el histórico. | P15: Catálogo
... A112: D11.07 | B112: D11 | C112: Evidencia histórica disponible | D112: Complementaria | E112: Cantidad y similitud | F112: Vigencia de los comparables | G112: ¿Los comparables son recientes y con proceso y tecnología vigentes? | H112: Fechas y contexto. | I112: Obsoletos. | J112: > 5 años. | K112: 2–5 años. | L112: < 2 años y vigentes. | M112: 1 | N112: No | O112: Los comparables no son vigentes. | P112: Catálogo

Sheet Parametros
A1: Parámetros del modelo de madurez para estimación
A2: Los valores en azul con fondo amarillo son editables; todas las hojas se recalculan a partir de ellos.
A3: Pesos por dimensión | H3: Arquetipos | I3: Tipos de desarrollo | J3: Entorno tecnológico | K3: Contexto de ejecución | L3: Sector | M3: Sí / No
A4: Código | B4: Dimensión | C4: Tipo | D4: Peso | E4: Justificación del peso | H4: Aplicaciones y soluciones digitales | I4: Nuevo desarrollo | J4: T1 - Conocida | K4: Estable | L4: Gobierno | M4: Sí
A5: D1 | B5: Tipo de desarrollo | C5: Núcleo | D5: 0.12 | E5: Define si el tamaño se mide como producto completo o como cambio; condiciona la selección de comparables. | H5: Integración e interoperabilidad | I5: Enhancement / evolutivo | J5: T2 - Parcialmente conocida | K5: Parcialmente conocido | L5: Financiero | M5: No
A6: D2 | B6: Tipo de solución / arquetipo | C6: Núcleo | D6: 0.11 | E6: Determina drivers de esfuerzo y el grupo histórico de referencia. | H6: Datos, analítica e inteligencia artificial | I6: Modernización / redevelopment | J6: T3 - Nueva | K6: Incierto | L6: Salud
A7: D3 | B7: Tamaño funcional | C7: Núcleo | D7: 0.18 | E7: Principal variable explicativa del esfuerzo; por eso recibe el mayor peso. | H7: Plataforma, infraestructura y DevOps | I7: Mantenimiento | J7: T4 - Experimental | L7: Comercio
A8: D4 | B8: Complejidad | C8: Núcleo | D8: 0.15 | E8: Ajusta la productividad sobre el tamaño; captura lo que el tamaño funcional no mide (reglas, algoritmos, RNF). | H8: Seguridad, identidad y confianza digital | L8: Telecomunicaciones
A9: D5 | B9: Integración / interdependencia | C9: Núcleo | D9: 0.14 | E9: Las interfaces concentran incertidumbre y dependencias con terceros. | H9: Modernización y migración | L9: Otros
A10: D6 | B10: Novedad y reutilización | C10: Complementaria | D10: 0.05 | E10: Modula el esfuerzo (reuso vs. construcción).
A11: D7 | B11: Entorno tecnológico | C11: Complementaria | D11: 0.05 | E11: Afecta la productividad por curva de aprendizaje.
A12: D8 | B12: Madurez del alcance | C12: Complementaria | D12: 0.07 | E12: Visión transversal del estado de la documentación; mayor peso entre complementarias.
A13: D9 | B13: Contexto de ejecución | C13: Complementaria | D13: 0.05 | E13: Afecta la capacidad y la productividad de ejecución.
A14: D10 | B14: Sector / contexto de negocio | C14: Complementaria | D14: 0.03 | E14: Restricciones externas; bajo impacto directo en tamaño.
A15: D11 | B15: Evidencia histórica disponible | C15: Complementaria | D15: 0.05 | E15: Condiciona la técnica de estimación y la confianza en la conversión tamaño → esfuerzo.
C16: Total | D16: =SUM(D5:D15) -> 1 | E16: =IF(ABS(D16-1)<0.0001,"OK: los pesos suman 100%","⚠ Los pesos deben sumar 100%") -> OK: los pesos suman 100%
C17: Peso núcleo | D17: =SUMIF(C5:C15,"Núcleo",D5:D15) -> 0.7 | E17: =IF(MIN(D5:D9)>MAX(D10:D15),"OK: cada dimensión núcleo pesa más que cualquier complementaria","⚠ Una complementaria pesa igual o más que una núcleo") -> OK: cada dimensión núcleo pesa más que cualquier complementaria
A20: Escala de calificación de criterios
A21: Puntaje | B21: Significado | C21: Descripción
A22: 0 | B22: Sin información | C22: No existe información o evidencia sobre el criterio.
A23: 1 | B23: Parcial / supuesto | C23: Información mencionada, verbal o supuesta; sin documento o sin cuantificar.
A24: 2 | B24: Definido con vacíos | C24: Información documentada pero incompleta o sin validar.
A25: 3 | B25: Completo y validado | C25: Información completa, cuantificada, documentada y validada por el responsable.
A26: N/A | B26: No aplica | C26: Solo en criterios marcados como «Admite N/A». Se excluye del máximo posible.
A28: Niveles de madurez (dimensión y general)
A29: Límite inferior | B29: Nivel | C29: N° | D29: Interpretación | E29: Técnica de estimación sugerida
A30: 0 | B30: N1 - Incipiente | C30: 1 | D30: Información insuficiente; la estimación sería una conjetura. | E30: Juicio experto / Delphi con rango amplio; priorizar levantamiento de información antes de comprometer una cifra.
A31: 0.2 | B31: N2 - Preliminar | C31: 2 | D31: Visión general con vacíos críticos. | E31: Juicio experto + analogía; estimación de orden de magnitud.
A32: 0.4 | B32: N3 - Intermedio | C32: 3 | D32: Alcance principal conocido; faltan detalles relevantes. | E32: Analogía con histórico + descomposición (WBS); estimación preliminar.
A33: 0.6 | B33: N4 - Definido | C33: 4 | D33: Alcance definido y mayormente cuantificado. | E33: Tamaño funcional + productividad histórica, contrastado con descomposición.
A34: 0.8 | B34: N5 - Validado | C34: 5 | D34: Información completa, cuantificada y validada. | E34: Tamaño funcional + modelo paramétrico calibrado; desempeño empírico si el equipo es conocido.
A36: Regla de tope por dimensiones núcleo
A37: Umbral mínimo de madurez núcleo | B37: 0.4 | C37: Si alguna dimensión núcleo queda por debajo de este umbral…
A38: Nivel general máximo permitido | B38: 3 | C38: …la madurez general no puede superar este nivel (evita que las complementarias compensen vacíos críticos).
A40: Clases de tamaño (por N° de procesos funcionales)
A41: Mínimo de procesos | B41: Clase | C41: Rango del catálogo
A42: 1 | B42: XS | C42: 1–5
A43: 6 | B43: S | C43: 6–15
A44: 16 | B44: M | C44: 16–30
A45: 31 | B45: L | C45: 31–60
...

Sheet Ficha
A1: Ficha de evaluación de madurez para estimación
A2: Ingresar datos solo en celdas amarillas (texto azul). Puntajes de criterios: 0, 1, 2, 3 o N/A (solo si la rúbrica lo admite). Criterios núcleo sin calificar cuentan como 0. Una dimensión complementaria sin ningún criterio calificado se excluye del cálculo.
A4: Proyecto
A5: Cliente / área
A6: Evaluador(es)
A7: Fecha de evaluación
A8: Momento de estimación
A9: Fuentes revisadas
A10: Versión de la ficha
A12: PARTE A · CARACTERIZACIÓN DEL PROYECTO (valores de clasificación del catálogo)
A13: Dimensión | D13: Variable | E13: Valor (ingresar) | G13: Clasificación resultante | H13: Regla aplicada
A14: D1 · Tipo de desarrollo | D14: % del alcance: nuevo desarrollo | G14: =IF(SUM(E14:E17)=0,"Sin datos",INDEX(Parametros!$I$4:$I$7,MATCH(MAX(E14:E17),E14:E17,0))) -> Sin datos | H14: Componente predominante (mayor %). Los cuatro porcentajes deben sumar 100%.
D15: % del alcance: enhancement / evolutivo | G15: =IF(COUNT(E14:E17)=0,"",IF(ABS(SUM(E14:E17)-1)<0.001,"Composición suma 100%","⚠ La composición no suma 100%"))
D16: % del alcance: modernización / redevelopment
D17: % del alcance: mantenimiento (correctivo / menor)
A18: D2 · Tipo de solución / arquetipo | D18: Arquetipo principal | G18: =IF(E18="","Sin asignar",E18) -> Sin asignar | H18: Principal = trabajo que explica la mayor proporción del esfuerzo esperado, no el componente más visible.
D19: Arquetipos secundarios (texto)
D20: % del esfuerzo del arquetipo principal | G20: =IF(E20="","",IF(E20>=0.5,"Predominio claro","Predominio débil: revisar secundarios"))
A21: D3 · Tamaño funcional | D21: N° de procesos funcionales identificados | G21: =IF(N(E21)=0,"Sin datos","Clase "&LOOKUP(E21,Parametros!$A$42:$A$46,Parametros!$B$42:$B$46)) -> Sin datos | H21: XS 1–5 · S 6–15 · M 16–30 · L 31–60 · XL >60 procesos. Aproximación = procesos × promedio.
D22: Puntos de función promedio por proceso (vacío = referencia) | G22: =IF(N(E21)=0,"","≈ "&TEXT(E21*IF(N(E22)=0,Parametros!$B$49,E22),"0")&" PF (aproximación)")
D23: Tamaño medido en puntos de función (si existe) | G23: =IF(N(E23)=0,"Sin medición detallada","Medido: "&E23&" PF") -> Sin medición detallada
A24: D4 · Complejidad | D24: Factor reglas de negocio (0 simples · 1 moderadas · 2 complejas) | G24: =IF(COUNT(E24:E28)=0,"Sin datos","Puntaje "&SUM(E24:E28)&" / 10") -> Sin datos | H24: Suma 0–10: 0–2 Baja · 3–5 Media · 6–8 Alta · 9–10 Muy alta.
D25: Factor arquitectura (0 conocida · 1 algunas novedades · 2 nueva/sofisticada) | G25: =IF(COUNT(E24:E28)=0,"","Complejidad "&LOOKUP(SUM(E24:E28),Parametros!$A$53:$A$56,Parametros!$B$53:$B$56))
D26: Factor seguridad (0 estándar · 1 elevada · 2 crítica)
D27: Factor procesamiento (0 simple · 1 medio · 2 complejo/tiempo real)
D28: Factor dependencias (0 pocas · 1 varias · 2 muchas/críticas)
A29: D5 · Integración | D29: N° de interfaces | G29: =IF(E29="","Sin datos",IF(E29=0,"I0 - Sin interfaces",IF(OR(E29>5,E31="Sí"),"I3 - Alta",IF(OR(E29>=3,E30="Sí"),"I2 - Media","I1 - Baja")))) -> Sin datos | H29: I0 sin interfaces · I1 1–2 simples · I2 3–5 o alguna compleja · I3 >5, críticos, protocolos no conocidos o múltiples terceros.
D30: ¿Alguna interfaz compleja?
D31: ¿Sistemas críticos, protocolos no conocidos o múltiples terceros?
A32: D6 · Reutilización | D32: % del alcance reutilizable | G32: =IF(E32="","Sin datos",IF(E32>0.7,"R1 - Alta reutilización",IF(E32>=0.4,"R2 - Media",IF(E32>=0.1,"R3 - Baja","R4 - Nuevo")))) -> Sin datos | H32: R1 >70% · R2 40–70% · R3 10–40% · R4 <10%.
A33: D7 · Entorno tecnológico | D33: Familiaridad tecnológica del equipo | G33: =IF(E33="","Sin datos",E33) -> Sin datos | H33: T1 Conocida · T2 Parcialmente conocida · T3 Nueva · T4 Experimental.
A34: D8 · Madurez del alcance | D34: Elementos del checklist con puntaje ≥ 2 (cálculo automático, D8.01–D8.08) | E34: =COUNTIF(F165:F172,">=2") -> 0 | G34: =IF(COUNT(F165:F172)=0,"Sin datos",IF(E34<=2,"M1 - Idea",IF(E34<=4,"M2 - Preliminar",IF(E34<=6,"M3 - Definido","M4 - Validado")))) -> Sin datos | H34: M1 0–2 · M2 3–4 · M3 5–6 · M4 7–8 elementos.
A35: D9 · Contexto de ejecución | D35: Condición del contexto de ejecución | G35: =IF(E35="","Sin datos",E35) -> Sin datos | H35: Estable · Parcialmente conocido · Incierto.
A36: D10 · Sector | D36: Sector del cliente | G36: =IF(E36="","Sin datos",E36) -> Sin datos | H36: Gobierno · Financiero · Salud · Comercio · Telecomunicaciones · Otros.
A37: D11 · Evidencia histórica | D37: N° de proyectos comparables | G37: =IF(E37="","Sin datos",IF(E37<=1,"E1 - Muy baja",IF(E37<=3,"E2 - Baja",IF(E37<=7,"E3 - Media","E4 - Alta")))) -> Sin datos | H37: E1 0–1 · E2 2–3 · E3 4–7 · E4 ≥8 comparables.
A40: RESUMEN DE MADUREZ (cálculo automático)
A41: Dimensión | D41: Principal brecha identificada | E41: Peso | F41: Madurez | G41: Nivel | H41: Tipo | I41: Aporte a la madurez general | J41: ¿Incluida en el cálculo?
A42: D1 · Tipo de desarrollo | D42: =IF(MAX(K81:K92)=0,"Sin brechas relevantes",INDEX(J81:J92,MATCH(MAX(K81:K92),K81:K92,0))) -> Sin evaluar (núcleo, cuenta como 0) – Frontera del software definida | E42: =Parametros!D5 -> 0.12 | F42: =IF(SUMIF($B$80:$B$240,"D1",$I$80:$I$240)=0,0,SUMIF($B$80:$B$240,"D1",$H$80:$H$240)/SUMIF($B$80:$B$240,"D1",$I$80:$I$240)) -> 0 | G42: =IF(J42="No","No evaluada",INDEX(Parametros!$B$30:$B$34,MATCH(F42,Parametros!$A$30:$A$34,1))) -> N1 - Incipiente | H42: =Parametros!C5 -> Núcleo | I42: =IF(J42="No",0,E42*F42/SUMPRODUCT($E$42:$E$52*($J$42:$J$52="Sí"))) -> 0 | J42: ="Sí" -> Sí
A43: D2 · Tipo de solución / arquetipo | D43: =IF(MAX(K94:K105)=0,"Sin brechas relevantes",INDEX(J94:J105,MATCH(MAX(K94:K105),K94:K105,0))) -> Sin evaluar (núcleo, cuenta como 0) – Drivers del arquetipo principal | E43: =Parametros!D6 -> 0.11 | F43: =IF(SUMIF($B$80:$B$240,"D2",$I$80:$I$240)=0,0,SUMIF($B$80:$B$240,"D2",$H$80:$H$240)/SUMIF($B$80:$B$240,"D2",$I$80:$I$240)) -> 0 | G43: =IF(J43="No","No evaluada",INDEX(Parametros!$B$30:$B$34,MATCH(F43,Parametros!$A$30:$A$34,1))) -> N1 - Incipiente | H43: =Parametros!C6 -> Núcleo | I43: =IF(J43="No",0,E43*F43/SUMPRODUCT($E$42:$E$52*($J$42:$J$52="Sí"))) -> 0 | J43: ="Sí" -> Sí
A44: D3 · Tamaño funcional | D44: =IF(MAX(K107:K120)=0,"Sin brechas relevantes",INDEX(J107:J120,MATCH(MAX(K107:K120),K107:K120,0))) -> Sin evaluar (núcleo, cuenta como 0) – Unidad objetiva y clase de tamaño | E44: =Parametros!D7 -> 0.18 | F44: =IF(SUMIF($B$80:$B$240,"D3",$I$80:$I$240)=0,0,SUMIF($B$80:$B$240,"D3",$H$80:$H$240)/SUMIF($B$80:$B$240,"D3",$I$80:$I$240)) -> 0 | G44: =IF(J44="No","No evaluada",INDEX(Parametros!$B$30:$B$34,MATCH(F44,Parametros!$A$30:$A$34,1))) -> N1 - Incipiente | H44: =Parametros!C7 -> Núcleo | I44: =IF(J44="No",0,E44*F44/SUMPRODUCT($E$42:$E$52*($J$42:$J$52="Sí"))) -> 0 | J44: ="Sí" -> Sí
...

Sheet Ejemplo
A1: Ficha de evaluación de madurez para estimación — EJEMPLO ILUSTRATIVO
A2: Ingresar datos solo en celdas amarillas (texto azul). Puntajes de criterios: 0, 1, 2, 3 o N/A (solo si la rúbrica lo admite). Criterios núcleo sin calificar cuentan como 0. Una dimensión complementaria sin ningún criterio calificado se excluye del cálculo.
A4: Proyecto | D4: Portal de gestión y firma electrónica de contratos
A5: Cliente / área | D5: Entidad pública – Dirección de Contratación
A6: Evaluador(es) | D6: Arquitecto de soluciones + Líder de estimación
A7: Fecha de evaluación | D7: 2026-09-22
A8: Momento de estimación | D8: Propuesta comercial (preventa)
A9: Fuentes revisadas | D9: Documento de alcance v0.3, 2 talleres, backlog Jira (34 ítems)
A10: Versión de la ficha | D10: 1.0
A12: PARTE A · CARACTERIZACIÓN DEL PROYECTO (valores de clasificación del catálogo)
A13: Dimensión | D13: Variable | E13: Valor (ingresar) | G13: Clasificación resultante | H13: Regla aplicada
A14: D1 · Tipo de desarrollo | D14: % del alcance: nuevo desarrollo | E14: 0.75 | G14: =IF(SUM(E14:E17)=0,"Sin datos",INDEX(Parametros!$I$4:$I$7,MATCH(MAX(E14:E17),E14:E17,0))) -> Nuevo desarrollo | H14: Componente predominante (mayor %). Los cuatro porcentajes deben sumar 100%.
D15: % del alcance: enhancement / evolutivo | E15: 0.25 | G15: =IF(COUNT(E14:E17)=0,"",IF(ABS(SUM(E14:E17)-1)<0.001,"Composición suma 100%","⚠ La composición no suma 100%")) -> Composición suma 100%
D16: % del alcance: modernización / redevelopment | E16: 0
D17: % del alcance: mantenimiento (correctivo / menor) | E17: 0
A18: D2 · Tipo de solución / arquetipo | D18: Arquetipo principal | E18: Aplicaciones y soluciones digitales | G18: =IF(E18="","Sin asignar",E18) -> Aplicaciones y soluciones digitales | H18: Principal = trabajo que explica la mayor proporción del esfuerzo esperado, no el componente más visible.
D19: Arquetipos secundarios (texto) | E19: Seguridad, identidad y confianza digital; Integración e interoperabilidad
D20: % del esfuerzo del arquetipo principal | E20: 0.6 | G20: =IF(E20="","",IF(E20>=0.5,"Predominio claro","Predominio débil: revisar secundarios")) -> Predominio claro
A21: D3 · Tamaño funcional | D21: N° de procesos funcionales identificados | E21: 34 | G21: =IF(N(E21)=0,"Sin datos","Clase "&LOOKUP(E21,Parametros!$A$42:$A$46,Parametros!$B$42:$B$46)) -> Clase L | H21: XS 1–5 · S 6–15 · M 16–30 · L 31–60 · XL >60 procesos. Aproximación = procesos × promedio.
D22: Puntos de función promedio por proceso (vacío = referencia) | G22: =IF(N(E21)=0,"","≈ "&TEXT(E21*IF(N(E22)=0,Parametros!$B$49,E22),"0")&" PF (aproximación)") -> ≈ 272 PF (aproximación)
D23: Tamaño medido en puntos de función (si existe) | G23: =IF(N(E23)=0,"Sin medición detallada","Medido: "&E23&" PF") -> Sin medición detallada
A24: D4 · Complejidad | D24: Factor reglas de negocio (0 simples · 1 moderadas · 2 complejas) | E24: 1 | G24: =IF(COUNT(E24:E28)=0,"Sin datos","Puntaje "&SUM(E24:E28)&" / 10") -> Puntaje 7 / 10 | H24: Suma 0–10: 0–2 Baja · 3–5 Media · 6–8 Alta · 9–10 Muy alta.
D25: Factor arquitectura (0 conocida · 1 algunas novedades · 2 nueva/sofisticada) | E25: 1 | G25: =IF(COUNT(E24:E28)=0,"","Complejidad "&LOOKUP(SUM(E24:E28),Parametros!$A$53:$A$56,Parametros!$B$53:$B$56)) -> Complejidad Alta
D26: Factor seguridad (0 estándar · 1 elevada · 2 crítica) | E26: 2
D27: Factor procesamiento (0 simple · 1 medio · 2 complejo/tiempo real) | E27: 1
D28: Factor dependencias (0 pocas · 1 varias · 2 muchas/críticas) | E28: 2
A29: D5 · Integración | D29: N° de interfaces | E29: 4 | G29: =IF(E29="","Sin datos",IF(E29=0,"I0 - Sin interfaces",IF(OR(E29>5,E31="Sí"),"I3 - Alta",IF(OR(E29>=3,E30="Sí"),"I2 - Media","I1 - Baja")))) -> I2 - Media | H29: I0 sin interfaces · I1 1–2 simples · I2 3–5 o alguna compleja · I3 >5, críticos, protocolos no conocidos o múltiples terceros.
D30: ¿Alguna interfaz compleja? | E30: Sí
D31: ¿Sistemas críticos, protocolos no conocidos o múltiples terceros? | E31: No
A32: D6 · Reutilización | D32: % del alcance reutilizable | E32: 0.3 | G32: =IF(E32="","Sin datos",IF(E32>0.7,"R1 - Alta reutilización",IF(E32>=0.4,"R2 - Media",IF(E32>=0.1,"R3 - Baja","R4 - Nuevo")))) -> R3 - Baja | H32: R1 >70% · R2 40–70% · R3 10–40% · R4 <10%.
A33: D7 · Entorno tecnológico | D33: Familiaridad tecnológica del equipo | E33: T2 - Parcialmente conocida | G33: =IF(E33="","Sin datos",E33) -> T2 - Parcialmente conocida | H33: T1 Conocida · T2 Parcialmente conocida · T3 Nueva · T4 Experimental.
A34: D8 · Madurez del alcance | D34: Elementos del checklist con puntaje ≥ 2 (cálculo automático, D8.01–D8.08) | E34: =COUNTIF(F165:F172,">=2") -> 5 | G34: =IF(COUNT(F165:F172)=0,"Sin datos",IF(E34<=2,"M1 - Idea",IF(E34<=4,"M2 - Preliminar",IF(E34<=6,"M3 - Definido","M4 - Validado")))) -> M3 - Definido | H34: M1 0–2 · M2 3–4 · M3 5–6 · M4 7–8 elementos.
A35: D9 · Contexto de ejecución | D35: Condición del contexto de ejecución | E35: Parcialmente conocido | G35: =IF(E35="","Sin datos",E35) -> Parcialmente conocido | H35: Estable · Parcialmente conocido · Incierto.
A36: D10 · Sector | D36: Sector del cliente | E36: Gobierno | G36: =IF(E36="","Sin datos",E36) -> Gobierno | H36: Gobierno · Financiero · Salud · Comercio · Telecomunicaciones · Otros.
A37: D11 · Evidencia histórica | D37: N° de proyectos comparables | E37: 3 | G37: =IF(E37="","Sin datos",IF(E37<=1,"E1 - Muy baja",IF(E37<=3,"E2 - Baja",IF(E37<=7,"E3 - Media","E4 - Alta")))) -> E2 - Baja | H37: E1 0–1 · E2 2–3 · E3 4–7 · E4 ≥8 comparables.
A40: RESUMEN DE MADUREZ (cálculo automático)
A41: Dimensión | D41: Principal brecha identificada | E41: Peso | F41: Madurez | G41: Nivel | H41: Tipo | I41: Aporte a la madurez general | J41: ¿Incluida en el cálculo?
A42: D1 · Tipo de desarrollo | D42: =IF(MAX(K81:K92)=0,"Sin brechas relevantes",INDEX(J81:J92,MATCH(MAX(K81:K92),K81:K92,0))) -> No se detalla qué cambia en las funcionalidades existentes. En evolutivos el tamaño es la suma de movimientos de datos agregados, modificados y eliminados; identificarlos. | E42: =Parametros!D5 -> 0.12 | F42: =IF(SUMIF($B$80:$B$240,"D1",$I$80:$I$240)=0,0,SUMIF($B$80:$B$240,"D1",$H$80:$H$240)/SUMIF($B$80:$B$240,"D1",$I$80:$I$240)) -> 0.6 | G42: =IF(J42="No","No evaluada",INDEX(Parametros!$B$30:$B$34,MATCH(F42,Parametros!$A$30:$A$34,1))) -> N4 - Definido | H42: =Parametros!C5 -> Núcleo | I42: =IF(J42="No",0,E42*F42/SUMPRODUCT($E$42:$E$52*($J$42:$J$52="Sí"))) -> 0.072 | J42: ="Sí" -> Sí
A43: D2 · Tipo de solución / arquetipo | D43: =IF(MAX(K94:K105)=0,"Sin brechas relevantes",INDEX(J94:J105,MATCH(MAX(K94:K105),K94:K105,0))) -> Los drivers de los arquetipos secundarios no están cuantificados. | E43: =Parametros!D6 -> 0.11 | F43: =IF(SUMIF($B$80:$B$240,"D2",$I$80:$I$240)=0,0,SUMIF($B$80:$B$240,"D2",$H$80:$H$240)/SUMIF($B$80:$B$240,"D2",$I$80:$I$240)) -> 0.71014493 | G43: =IF(J43="No","No evaluada",INDEX(Parametros!$B$30:$B$34,MATCH(F43,Parametros!$A$30:$A$34,1))) -> N4 - Definido | H43: =Parametros!C6 -> Núcleo | I43: =IF(J43="No",0,E43*F43/SUMPRODUCT($E$42:$E$52*($J$42:$J$52="Sí"))) -> 0.078115942 | J43: ="Sí" -> Sí
A44: D3 · Tamaño funcional | D44: =IF(MAX(K107:K120)=0,"Sin brechas relevantes",INDEX(J107:J120,MATCH(MAX(K107:K120),K107:K120,0))) -> No se identifican los movimientos de datos (Entradas, Salidas, Lecturas, Escrituras); el tamaño queda como aproximación. Medir al menos una muestra representativa. | E44: =Parametros!D7 -> 0.18 | F44: =IF(SUMIF($B$80:$B$240,"D3",$I$80:$I$240)=0,0,SUMIF($B$80:$B$240,"D3",$H$80:$H$240)/SUMIF($B$80:$B$240,"D3",$I$80:$I$240)) -> 0.49462366 | G44: =IF(J44="No","No evaluada",INDEX(Parametros!$B$30:$B$34,MATCH(F44,Parametros!$A$30:$A$34,1))) -> N3 - Intermedio | H44: =Parametros!C7 -> Núcleo | I44: =IF(J44="No",0,E44*F44/SUMPRODUCT($E$42:$E$52*($J$42:$J$52="Sí"))) -> 0.089032258 | J44: ="Sí" -> Sí
...

Sheet Resultados
B1: Resultados de la evaluación de madurez
B3: Ficha a analizar (seleccionar): | C3: Ejemplo | D3: Todas las cifras de esta hoja se leen de la ficha seleccionada (Ejemplo o Ficha).
B5: Proyecto | C5: =IF(INDIRECT("'"&$C$3&"'!D4")="","",INDIRECT("'"&$C$3&"'!D4")) -> Portal de gestión y firma electrónica de contratos
B6: Cliente / área | C6: =IF(INDIRECT("'"&$C$3&"'!D5")="","",INDIRECT("'"&$C$3&"'!D5")) -> Entidad pública – Dirección de Contratación
B7: Evaluador(es) | C7: =IF(INDIRECT("'"&$C$3&"'!D6")="","",INDIRECT("'"&$C$3&"'!D6")) -> Arquitecto de soluciones + Líder de estimación
B8: Fecha de evaluación | C8: =IF(INDIRECT("'"&$C$3&"'!D7")="","",INDIRECT("'"&$C$3&"'!D7")) -> 2026-09-22
B9: Momento de estimación | C9: =IF(INDIRECT("'"&$C$3&"'!D8")="","",INDIRECT("'"&$C$3&"'!D8")) -> Propuesta comercial (preventa)
B11: Madurez general | C11: Nivel final | F11: Arquetipo principal | O11: Técnica de estimación sugerida
B12: =INDIRECT("'"&$C$3&"'!F53") -> 0.56716233 | C12: =INDIRECT("'"&$C$3&"'!G55") -> N3 - Intermedio | F12: =INDIRECT("'"&$C$3&"'!G18") -> Aplicaciones y soluciones digitales | O12: =INDIRECT("'"&$C$3&"'!D57") -> Analogía con histórico + descomposición (WBS); estimación preliminar.
B14: Madurez por dimensión
B15: Dimensión | C15: Tipo | D15: Peso | E15: Madurez | F15: Nivel | G15: Aporte | H15: N° criterios | I15: En 0 | J15: En 1 | K15: En 2 | L15: En 3 | M15: N/A | N15: Sin evaluar | O15: Principal brecha
B16: D1 · Tipo de desarrollo | C16: =INDIRECT("'"&$C$3&"'!H42") -> Núcleo | D16: =INDIRECT("'"&$C$3&"'!E42") -> 0.12 | E16: =INDIRECT("'"&$C$3&"'!F42") -> 0.6 | F16: =INDIRECT("'"&$C$3&"'!G42") -> N4 - Definido | G16: =INDIRECT("'"&$C$3&"'!I42") -> 0.072 | H16: =COUNTIF(INDIRECT("'"&$C$3&"'!$B$80:$B$240"),"D1") -> 12 | I16: =COUNTIFS(INDIRECT("'"&$C$3&"'!$B$80:$B$240"),"D1",INDIRECT("'"&$C$3&"'!$F$80:$F$240"),0) -> 0 | J16: =COUNTIFS(INDIRECT("'"&$C$3&"'!$B$80:$B$240"),"D1",INDIRECT("'"&$C$3&"'!$F$80:$F$240"),1) -> 4 | K16: =COUNTIFS(INDIRECT("'"&$C$3&"'!$B$80:$B$240"),"D1",INDIRECT("'"&$C$3&"'!$F$80:$F$240"),2) -> 5 | L16: =COUNTIFS(INDIRECT("'"&$C$3&"'!$B$80:$B$240"),"D1",INDIRECT("'"&$C$3&"'!$F$80:$F$240"),3) -> 2 | M16: =COUNTIFS(INDIRECT("'"&$C$3&"'!$B$80:$B$240"),"D1",INDIRECT("'"&$C$3&"'!$F$80:$F$240"),"N/A") -> 1 | N16: =H16-SUM(I16:M16) -> 0 | O16: =INDIRECT("'"&$C$3&"'!D42") -> No se detalla qué cambia en las funcionalidades existentes. En evolutivos el tamaño es la suma de movimientos de datos agregados, modificados y eliminados; identificarlos.
B17: D2 · Tipo de solución / arquetipo | C17: =INDIRECT("'"&$C$3&"'!H43") -> Núcleo | D17: =INDIRECT("'"&$C$3&"'!E43") -> 0.11 | E17: =INDIRECT("'"&$C$3&"'!F43") -> 0.71014493 | F17: =INDIRECT("'"&$C$3&"'!G43") -> N4 - Definido | G17: =INDIRECT("'"&$C$3&"'!I43") -> 0.078115942 | H17: =COUNTIF(INDIRECT("'"&$C$3&"'!$B$80:$B$240"),"D2") -> 12 | I17: =COUNTIFS(INDIRECT("'"&$C$3&"'!$B$80:$B$240"),"D2",INDIRECT("'"&$C$3&"'!$F$80:$F$240"),0) -> 0 | J17: =COUNTIFS(INDIRECT("'"&$C$3&"'!$B$80:$B$240"),"D2",INDIRECT("'"&$C$3&"'!$F$80:$F$240"),1) -> 2 | K17: =COUNTIFS(INDIRECT("'"&$C$3&"'!$B$80:$B$240"),"D2",INDIRECT("'"&$C$3&"'!$F$80:$F$240"),2) -> 7 | L17: =COUNTIFS(INDIRECT("'"&$C$3&"'!$B$80:$B$240"),"D2",INDIRECT("'"&$C$3&"'!$F$80:$F$240"),3) -> 3 | M17: =COUNTIFS(INDIRECT("'"&$C$3&"'!$B$80:$B$240"),"D2",INDIRECT("'"&$C$3&"'!$F$80:$F$240"),"N/A") -> 0 | N17: =H17-SUM(I17:M17) -> 0 | O17: =INDIRECT("'"&$C$3&"'!D43") -> Los drivers de los arquetipos secundarios no están cuantificados.
B18: D3 · Tamaño funcional | C18: =INDIRECT("'"&$C$3&"'!H44") -> Núcleo | D18: =INDIRECT("'"&$C$3&"'!E44") -> 0.18 | E18: =INDIRECT("'"&$C$3&"'!F44") -> 0.49462366 | F18: =INDIRECT("'"&$C$3&"'!G44") -> N3 - Intermedio | G18: =INDIRECT("'"&$C$3&"'!I44") -> 0.089032258 | H18: =COUNTIF(INDIRECT("'"&$C$3&"'!$B$80:$B$240"),"D3") -> 14 | I18: =COUNTIFS(INDIRECT("'"&$C$3&"'!$B$80:$B$240"),"D3",INDIRECT("'"&$C$3&"'!$F$80:$F$240"),0) -> 1 | J18: =COUNTIFS(INDIRECT("'"&$C$3&"'!$B$80:$B$240"),"D3",INDIRECT("'"&$C$3&"'!$F$80:$F$240"),1) -> 7 | K18: =COUNTIFS(INDIRECT("'"&$C$3&"'!$B$80:$B$240"),"D3",INDIRECT("'"&$C$3&"'!$F$80:$F$240"),2) -> 6 | L18: =COUNTIFS(INDIRECT("'"&$C$3&"'!$B$80:$B$240"),"D3",INDIRECT("'"&$C$3&"'!$F$80:$F$240"),3) -> 0 | M18: =COUNTIFS(INDIRECT("'"&$C$3&"'!$B$80:$B$240"),"D3",INDIRECT("'"&$C$3&"'!$F$80:$F$240"),"N/A") -> 0 | N18: =H18-SUM(I18:M18) -> 0 | O18: =INDIRECT("'"&$C$3&"'!D44") -> No se identifican los movimientos de datos (Entradas, Salidas, Lecturas, Escrituras); el tamaño queda como aproximación. Medir al menos una muestra representativa.
B19: D4 · Complejidad | C19: =INDIRECT("'"&$C$3&"'!H45") -> Núcleo | D19: =INDIRECT("'"&$C$3&"'!E45") -> 0.15 | E19: =INDIRECT("'"&$C$3&"'!F45") -> 0.58974359 | F19: =INDIRECT("'"&$C$3&"'!G45") -> N3 - Intermedio | G19: =INDIRECT("'"&$C$3&"'!I45") -> 0.088461538 | H19: =COUNTIF(INDIRECT("'"&$C$3&"'!$B$80:$B$240"),"D4") -> 12 | I19: =COUNTIFS(INDIRECT("'"&$C$3&"'!$B$80:$B$240"),"D4",INDIRECT("'"&$C$3&"'!$F$80:$F$240"),0) -> 1 | J19: =COUNTIFS(INDIRECT("'"&$C$3&"'!$B$80:$B$240"),"D4",INDIRECT("'"&$C$3&"'!$F$80:$F$240"),1) -> 3 | K19: =COUNTIFS(INDIRECT("'"&$C$3&"'!$B$80:$B$240"),"D4",INDIRECT("'"&$C$3&"'!$F$80:$F$240"),2) -> 6 | L19: =COUNTIFS(INDIRECT("'"&$C$3&"'!$B$80:$B$240"),"D4",INDIRECT("'"&$C$3&"'!$F$80:$F$240"),3) -> 2 | M19: =COUNTIFS(INDIRECT("'"&$C$3&"'!$B$80:$B$240"),"D4",INDIRECT("'"&$C$3&"'!$F$80:$F$240"),"N/A") -> 0 | N19: =H19-SUM(I19:M19) -> 0 | O19: =INDIRECT("'"&$C$3&"'!D45") -> Los requisitos de seguridad no están especificados ni clasificados.
B20: D5 · Integración / interdependencia | C20: =INDIRECT("'"&$C$3&"'!H46") -> Núcleo | D20: =INDIRECT("'"&$C$3&"'!E46") -> 0.14 | E20: =INDIRECT("'"&$C$3&"'!F46") -> 0.51190476 | F20: =INDIRECT("'"&$C$3&"'!G46") -> N3 - Intermedio | G20: =INDIRECT("'"&$C$3&"'!I46") -> 0.071666667 | H20: =COUNTIF(INDIRECT("'"&$C$3&"'!$B$80:$B$240"),"D5") -> 13 | I20: =COUNTIFS(INDIRECT("'"&$C$3&"'!$B$80:$B$240"),"D5",INDIRECT("'"&$C$3&"'!$F$80:$F$240"),0) -> 1 | J20: =COUNTIFS(INDIRECT("'"&$C$3&"'!$B$80:$B$240"),"D5",INDIRECT("'"&$C$3&"'!$F$80:$F$240"),1) -> 5 | K20: =COUNTIFS(INDIRECT("'"&$C$3&"'!$B$80:$B$240"),"D5",INDIRECT("'"&$C$3&"'!$F$80:$F$240"),2) -> 6 | L20: =COUNTIFS(INDIRECT("'"&$C$3&"'!$B$80:$B$240"),"D5",INDIRECT("'"&$C$3&"'!$F$80:$F$240"),3) -> 1 | M20: =COUNTIFS(INDIRECT("'"&$C$3&"'!$B$80:$B$240"),"D5",INDIRECT("'"&$C$3&"'!$F$80:$F$240"),"N/A") -> 0 | N20: =H20-SUM(I20:M20) -> 0 | O20: =INDIRECT("'"&$C$3&"'!D46") -> No está definido el manejo de errores (reintentos, idempotencia, conciliación).
B21: D6 · Novedad y reutilización | C21: =INDIRECT("'"&$C$3&"'!H47") -> Complementaria | D21: =INDIRECT("'"&$C$3&"'!E47") -> 0.05 | E21: =INDIRECT("'"&$C$3&"'!F47") -> 0.47222222 | F21: =INDIRECT("'"&$C$3&"'!G47") -> N3 - Intermedio | G21: =INDIRECT("'"&$C$3&"'!I47") -> 0.023611111 | H21: =COUNTIF(INDIRECT("'"&$C$3&"'!$B$80:$B$240"),"D6") -> 7 | I21: =COUNTIFS(INDIRECT("'"&$C$3&"'!$B$80:$B$240"),"D6",INDIRECT("'"&$C$3&"'!$F$80:$F$240"),0) -> 0 | J21: =COUNTIFS(INDIRECT("'"&$C$3&"'!$B$80:$B$240"),"D6",INDIRECT("'"&$C$3&"'!$F$80:$F$240"),1) -> 3 | K21: =COUNTIFS(INDIRECT("'"&$C$3&"'!$B$80:$B$240"),"D6",INDIRECT("'"&$C$3&"'!$F$80:$F$240"),2) -> 3 | L21: =COUNTIFS(INDIRECT("'"&$C$3&"'!$B$80:$B$240"),"D6",INDIRECT("'"&$C$3&"'!$F$80:$F$240"),3) -> 0 | M21: =COUNTIFS(INDIRECT("'"&$C$3&"'!$B$80:$B$240"),"D6",INDIRECT("'"&$C$3&"'!$F$80:$F$240"),"N/A") -> 1 | N21: =H21-SUM(I21:M21) -> 0 | O21: =INDIRECT("'"&$C$3&"'!D47") -> El reuso no está clasificado por funcionalidad; el porcentaje reutilizable es una suposición.
B22: D7 · Entorno tecnológico | C22: =INDIRECT("'"&$C$3&"'!H48") -> Complementaria | D22: =INDIRECT("'"&$C$3&"'!E48") -> 0.05 | E22: =INDIRECT("'"&$C$3&"'!F48") -> 0.68888889 | F22: =INDIRECT("'"&$C$3&"'!G48") -> N4 - Definido | G22: =INDIRECT("'"&$C$3&"'!I48") -> 0.034444444 | H22: =COUNTIF(INDIRECT("'"&$C$3&"'!$B$80:$B$240"),"D7") -> 7 | I22: =COUNTIFS(INDIRECT("'"&$C$3&"'!$B$80:$B$240"),"D7",INDIRECT("'"&$C$3&"'!$F$80:$F$240"),0) -> 0 | J22: =COUNTIFS(INDIRECT("'"&$C$3&"'!$B$80:$B$240"),"D7",INDIRECT("'"&$C$3&"'!$F$80:$F$240"),1) -> 2 | K22: =COUNTIFS(INDIRECT("'"&$C$3&"'!$B$80:$B$240"),"D7",INDIRECT("'"&$C$3&"'!$F$80:$F$240"),2) -> 3 | L22: =COUNTIFS(INDIRECT("'"&$C$3&"'!$B$80:$B$240"),"D7",INDIRECT("'"&$C$3&"'!$F$80:$F$240"),3) -> 2 | M22: =COUNTIFS(INDIRECT("'"&$C$3&"'!$B$80:$B$240"),"D7",INDIRECT("'"&$C$3&"'!$F$80:$F$240"),"N/A") -> 0 | N22: =H22-SUM(I22:M22) -> 0 | O22: =INDIRECT("'"&$C$3&"'!D48") -> No se conocen las restricciones tecnológicas del cliente.
B23: D8 · Madurez del alcance | C23: =INDIRECT("'"&$C$3&"'!H49") -> Complementaria | D23: =INDIRECT("'"&$C$3&"'!E49") -> 0.07 | E23: =INDIRECT("'"&$C$3&"'!F49") -> 0.56521739 | F23: =INDIRECT("'"&$C$3&"'!G49") -> N3 - Intermedio | G23: =INDIRECT("'"&$C$3&"'!I49") -> 0.039565217 | H23: =COUNTIF(INDIRECT("'"&$C$3&"'!$B$80:$B$240"),"D8") -> 11 | I23: =COUNTIFS(INDIRECT("'"&$C$3&"'!$B$80:$B$240"),"D8",INDIRECT("'"&$C$3&"'!$F$80:$F$240"),0) -> 0 | J23: =COUNTIFS(INDIRECT("'"&$C$3&"'!$B$80:$B$240"),"D8",INDIRECT("'"&$C$3&"'!$F$80:$F$240"),1) -> 5 | K23: =COUNTIFS(INDIRECT("'"&$C$3&"'!$B$80:$B$240"),"D8",INDIRECT("'"&$C$3&"'!$F$80:$F$240"),2) -> 4 | L23: =COUNTIFS(INDIRECT("'"&$C$3&"'!$B$80:$B$240"),"D8",INDIRECT("'"&$C$3&"'!$F$80:$F$240"),3) -> 2 | M23: =COUNTIFS(INDIRECT("'"&$C$3&"'!$B$80:$B$240"),"D8",INDIRECT("'"&$C$3&"'!$F$80:$F$240"),"N/A") -> 0 | N23: =H23-SUM(I23:M23) -> 0 | O23: =INDIRECT("'"&$C$3&"'!D49") -> No hay criterios de aceptación verificables; sin ellos el alcance de pruebas y la aceptación son inciertos.
B24: D9 · Contexto de ejecución | C24: =INDIRECT("'"&$C$3&"'!H50") -> Complementaria | D24: =INDIRECT("'"&$C$3&"'!E50") -> 0.05 | E24: =INDIRECT("'"&$C$3&"'!F50") -> 0.64583333 | F24: =INDIRECT("'"&$C$3&"'!G50") -> N4 - Definido | G24: =INDIRECT("'"&$C$3&"'!I50") -> 0.032291667 | H24: =COUNTIF(INDIRECT("'"&$C$3&"'!$B$80:$B$240"),"D9") -> 8 | I24: =COUNTIFS(INDIRECT("'"&$C$3&"'!$B$80:$B$240"),"D9",INDIRECT("'"&$C$3&"'!$F$80:$F$240"),0) -> 0 | J24: =COUNTIFS(INDIRECT("'"&$C$3&"'!$B$80:$B$240"),"D9",INDIRECT("'"&$C$3&"'!$F$80:$F$240"),1) -> 2 | K24: =COUNTIFS(INDIRECT("'"&$C$3&"'!$B$80:$B$240"),"D9",INDIRECT("'"&$C$3&"'!$F$80:$F$240"),2) -> 4 | L24: =COUNTIFS(INDIRECT("'"&$C$3&"'!$B$80:$B$240"),"D9",INDIRECT("'"&$C$3&"'!$F$80:$F$240"),3) -> 2 | M24: =COUNTIFS(INDIRECT("'"&$C$3&"'!$B$80:$B$240"),"D9",INDIRECT("'"&$C$3&"'!$F$80:$F$240"),"N/A") -> 0 | N24: =H24-SUM(I24:M24) -> 0 | O24: =INDIRECT("'"&$C$3&"'!D50") -> No se conocen las dependencias externas de ejecución ni sus tiempos.
B25: D10 · Sector / contexto de negocio | C25: =INDIRECT("'"&$C$3&"'!H51") -> Complementaria | D25: =INDIRECT("'"&$C$3&"'!E51") -> 0.03 | E25: =INDIRECT("'"&$C$3&"'!F51") -> 0.60606061 | F25: =INDIRECT("'"&$C$3&"'!G51") -> N4 - Definido | G25: =INDIRECT("'"&$C$3&"'!I51") -> 0.018181818 | H25: =COUNTIF(INDIRECT("'"&$C$3&"'!$B$80:$B$240"),"D10") -> 6 | I25: =COUNTIFS(INDIRECT("'"&$C$3&"'!$B$80:$B$240"),"D10",INDIRECT("'"&$C$3&"'!$F$80:$F$240"),0) -> 0 | J25: =COUNTIFS(INDIRECT("'"&$C$3&"'!$B$80:$B$240"),"D10",INDIRECT("'"&$C$3&"'!$F$80:$F$240"),1) -> 2 | K25: =COUNTIFS(INDIRECT("'"&$C$3&"'!$B$80:$B$240"),"D10",INDIRECT("'"&$C$3&"'!$F$80:$F$240"),2) -> 3 | L25: =COUNTIFS(INDIRECT("'"&$C$3&"'!$B$80:$B$240"),"D10",INDIRECT("'"&$C$3&"'!$F$80:$F$240"),3) -> 1 | M25: =COUNTIFS(INDIRECT("'"&$C$3&"'!$B$80:$B$240"),"D10",INDIRECT("'"&$C$3&"'!$F$80:$F$240"),"N/A") -> 0 | N25: =H25-SUM(I25:M25) -> 0 | O25: =INDIRECT("'"&$C$3&"'!D51") -> No se conocen los stakeholders ni el ciclo de aprobaciones.
B26: D11 · Evidencia histórica disponible | C26: =INDIRECT("'"&$C$3&"'!H52") -> Complementaria | D26: =INDIRECT("'"&$C$3&"'!E52") -> 0.05 | E26: =INDIRECT("'"&$C$3&"'!F52") -> 0.39583333 | F26: =INDIRECT("'"&$C$3&"'!G52") -> N2 - Preliminar | G26: =INDIRECT("'"&$C$3&"'!I52") -> 0.019791667 | H26: =COUNTIF(INDIRECT("'"&$C$3&"'!$B$80:$B$240"),"D11") -> 7 | I26: =COUNTIFS(INDIRECT("'"&$C$3&"'!$B$80:$B$240"),"D11",INDIRECT("'"&$C$3&"'!$F$80:$F$240"),0) -> 1 | J26: =COUNTIFS(INDIRECT("'"&$C$3&"'!$B$80:$B$240"),"D11",INDIRECT("'"&$C$3&"'!$F$80:$F$240"),1) -> 4 | K26: =COUNTIFS(INDIRECT("'"&$C$3&"'!$B$80:$B$240"),"D11",INDIRECT("'"&$C$3&"'!$F$80:$F$240"),2) -> 1 | L26: =COUNTIFS(INDIRECT("'"&$C$3&"'!$B$80:$B$240"),"D11",INDIRECT("'"&$C$3&"'!$F$80:$F$240"),3) -> 1 | M26: =COUNTIFS(INDIRECT("'"&$C$3&"'!$B$80:$B$240"),"D11",INDIRECT("'"&$C$3&"'!$F$80:$F$240"),"N/A") -> 0 | N26: =H26-SUM(I26:M26) -> 0 | O26: =INDIRECT("'"&$C$3&"'!D52") -> El tamaño de los comparables no está normalizado.
B27: Madurez general ponderada | D27: =SUM(D16:D26) -> 1 | E27: =INDIRECT("'"&$C$3&"'!F53") -> 0.56716233 | F27: =INDIRECT("'"&$C$3&"'!G55") -> N3 - Intermedio | G27: =SUM(G16:G26) -> 0.56716233 | H27: =SUM(H16:H26) -> 109 | I27: =SUM(I16:I26) -> 4 | J27: =SUM(J16:J26) -> 39 | K27: =SUM(K16:K26) -> 48 | L27: =SUM(L16:L26) -> 16 | M27: =SUM(M16:M26) -> 2 | N27: =SUM(N16:N26) -> 0 | O27: =INDIRECT("'"&$C$3&"'!G54") -> No aplica tope
B48: Caracterización del proyecto (valores del catálogo)
B49: D1 · Tipo de desarrollo predominante | C49: =IF(INDIRECT("'"&$C$3&"'!G14")="","",INDIRECT("'"&$C$3&"'!G14")) -> Nuevo desarrollo
B50: D1 · Control de composición | C50: =IF(INDIRECT("'"&$C$3&"'!G15")="","",INDIRECT("'"&$C$3&"'!G15")) -> Composición suma 100%
B51: D2 · Arquetipo principal | C51: =IF(INDIRECT("'"&$C$3&"'!G18")="","",INDIRECT("'"&$C$3&"'!G18")) -> Aplicaciones y soluciones digitales
B52: D2 · Arquetipos secundarios | C52: =IF(INDIRECT("'"&$C$3&"'!E19")="","",INDIRECT("'"&$C$3&"'!E19")) -> Seguridad, identidad y confianza digital; Integración e interoperabilidad
B53: D2 · Predominio del arquetipo | C53: =IF(INDIRECT("'"&$C$3&"'!G20")="","",INDIRECT("'"&$C$3&"'!G20")) -> Predominio claro
B54: D3 · Clase de tamaño | C54: =IF(INDIRECT("'"&$C$3&"'!G21")="","",INDIRECT("'"&$C$3&"'!G21")) -> Clase L
B55: D3 · Tamaño aproximado | C55: =IF(INDIRECT("'"&$C$3&"'!G22")="","",INDIRECT("'"&$C$3&"'!G22")) -> ≈ 272 PF (aproximación)
B56: D3 · Tamaño medido | C56: =IF(INDIRECT("'"&$C$3&"'!G23")="","",INDIRECT("'"&$C$3&"'!G23")) -> Sin medición detallada
B57: D4 · Puntaje de complejidad | C57: =IF(INDIRECT("'"&$C$3&"'!G24")="","",INDIRECT("'"&$C$3&"'!G24")) -> Puntaje 7 / 10
B58: D4 · Nivel de complejidad | C58: =IF(INDIRECT("'"&$C$3&"'!G25")="","",INDIRECT("'"&$C$3&"'!G25")) -> Complejidad Alta
B59: D5 · Nivel de integración | C59: =IF(INDIRECT("'"&$C$3&"'!G29")="","",INDIRECT("'"&$C$3&"'!G29")) -> I2 - Media
B60: D6 · Nivel de reutilización | C60: =IF(INDIRECT("'"&$C$3&"'!G32")="","",INDIRECT("'"&$C$3&"'!G32")) -> R3 - Baja
B61: D7 · Entorno tecnológico | C61: =IF(INDIRECT("'"&$C$3&"'!G33")="","",INDIRECT("'"&$C$3&"'!G33")) -> T2 - Parcialmente conocida
B62: D8 · Madurez del alcance (catálogo) | C62: =IF(INDIRECT("'"&$C$3&"'!G34")="","",INDIRECT("'"&$C$3&"'!G34")) -> M3 - Definido
B63: D9 · Contexto de ejecución | C63: =IF(INDIRECT("'"&$C$3&"'!G35")="","",INDIRECT("'"&$C$3&"'!G35")) -> Parcialmente conocido
B64: D10 · Sector | C64: =IF(INDIRECT("'"&$C$3&"'!G36")="","",INDIRECT("'"&$C$3&"'!G36")) -> Gobierno
...

Sheet Glosario
A1: Glosario de conceptos de medición funcional usados en el modelo
A2: Los criterios de Tamaño, Integración y Tipo de desarrollo aplican los conceptos del método de medición funcional COSMIC (ISO/IEC 19761). Se incluyen aquí para que el evaluador califique con el mismo significado.
A3: Concepto | B3: Definición | C3: Uso en la evaluación
A4: Propósito de la medición | B4: Razón por la cual se mide (p. ej. cotizar un proyecto). Determina qué se incluye y con qué detalle. | C4: D3.01
A5: Alcance de la medición | B5: Conjunto de requisitos funcionales y piezas de software incluidos en una medición. | C5: D3.01, D1.07
A6: Capa | B6: División funcional de la arquitectura (p. ej. aplicación, servicios, infraestructura) cuyos componentes se miden por separado. | C6: D1.08
A7: Componente par | B7: Pieza de software en la misma capa que intercambia datos con la que se mide; se trata como usuario funcional. | C7: D1.08, D5.02
A8: Frontera | B8: Límite conceptual entre el software medido y sus usuarios funcionales. | C8: D1.07, D5.02
A9: Usuario funcional | B9: Emisor o receptor de datos del software: persona (por rol), otro sistema, dispositivo o componente. | C9: D2.08, D3.03
A10: Evento desencadenante | B10: Suceso fuera del software (acción de usuario, mensaje, tiempo) que inicia un proceso funcional. | C10: D3.04
A11: Proceso funcional | B11: Conjunto único de movimientos de datos que responde a un evento desencadenante y termina cuando completa su respuesta. Unidad para contar «funcionalidades». | C11: D1.04, D3.05, Parte A (D3)
A12: Objeto de interés | B12: Cosa del negocio sobre la que el software almacena o procesa información (contrato, proveedor…). | C12: D3.06
A13: Grupo de datos | B13: Conjunto de atributos que describen un mismo objeto de interés. | C13: D3.06, D5.02
A14: Movimiento de datos | B14: Movimiento de un grupo de datos. Hay cuatro tipos: Entrada, Salida, Lectura y Escritura. Cada uno vale 1 punto de función. | C14: D3.07, D3.12
... A23: Requisito no funcional que genera funcionalidad | B23: Requisito de calidad que al detallarse se implementa como procesos funcionales (bitácoras, notificaciones, permisos). | C23: D3.10
